Workbook

Sheet Base Result
A1: Feature | B1: run 1 | C1: run 2 | D1: run 3 | E1: run 4 | F1: run 5 | G1: run 6 | H1: run 7 | I1: run 8 | J1: run 9 | K1: run 10 | L1: run 11 | M1: run 12 | N1: run 13 | O1: run 14 | P1: run 15 | Q1: run 16 | R1: run 17 | S1: run 18 | T1: run 19 | U1: run 20 | V1: run 21 | W1: run 22 | X1: run 23 | Y1: run 24 | Z1: run 25 | AA1: run 26 | AB1: run 27 | AC1: run 28 | AD1: run 29 | AE1: run 30 | AF1: run 31 | AG1: run 32 | AH1: run 33 | AI1: run 34 | AJ1: run 35 | AK1: run 36 | AL1: run 37 | AM1: run 38 | AN1: run 39 | AO1: run 40 | AP1: run 41 | AQ1: run 42 | AR1: run 43 | AS1: run 44 | AT1: run 45 | AU1: run 46 | AV1: run 47 | AW1: run 48 | AX1: run 49 | AY1: run 50 | AZ1: run 51 | BA1: run 52 | BB1: run 53 | BC1: run 54 | BD1: run 55 | BE1: run 56 | BF1: run 57 | BG1: run 58 | BH1: run 59 | BI1: run 60 | BJ1: run 61 | BK1: run 62 | BL1: run 63 | BM1: run 64 | BN1: run 65 | BO1: run 66 | BP1: run 67 | BQ1: run 68 | BR1: run 69 | BS1: run 70 | BT1: run 71 | BU1: run 72 | BV1: run 73 | BW1: run 74 | BX1: run 75 | BY1: run 76 | BZ1: run 77 | CA1: run 78 | CB1: run 79 | CC1: run 80 | CD1: run 81 | CE1: run 82 | CF1: run 83 | CG1: run 84 | CH1: run 85 | CI1: run 86 | CJ1: run 87 | CK1: run 88 | CL1: run 89 | CM1: run 90 | CN1: run 91 | CO1: run 92 | CP1: run 93 | CQ1: run 94 | CR1: run 95 | CS1: run 96 | CT1: run 97 | CU1: run 98 | CV1: run 99 | CW1: run 100
A2: feature_00 | B2: 0.72823858 | C2: 0.034302115 | D2: 0.35418245 | E2: 0.56817993 | F2: 0.27568886 | G2: 0.21853824 | H2: 0.34487651 | I2: 0.86488439 | J2: 0.15340423 | K2: 0.032392317 | L2: 0.098237241 | M2: 0.12547285 | N2: 0.24182605 | O2: 0.59197505 | P2: 0.35476647 | Q2: 0.56785308 | R2: 0.49109554 | S2: 0.20710014 | T2: 0.53079905 | U2: 0.87154546 | V2: 0.38242396 | W2: 0.88803294 | X2: 0.039847811 | Y2: 0.83121786 | Z2: 0.44396213 | AA2: 0.10904679 | AB2: 0.51892134 | AC2: 0.19859396 | AD2: 0.21283148 | AE2: 0.85241239 | AF2: 0.03346206 | AG2: 0.9853486 | AH2: 0.011566898 | AI2: 0.3388596 | AJ2: 0.26972115 | AK2: 0.41628081 | AL2: 0.93315195 | AM2: 0.11615611 | AN2: 0.27763366 | AO2: 0.57529027 | AP2: 0.82988869 | AQ2: 0.97223793 | AR2: 0.29461913 | AS2: 0.77810429 | AT2: 0.29915542 | AU2: 0.84327211 | AV2: 0.63171445 | AW2: 0.39941723 | AX2: 0.15109508 | AY2: 0.83399044 | AZ2: 0.92618472 | BA2: 0.78643047 | BB2: 0.68805124 | BC2: 0.29086524 | BD2: 0.16950503 | BE2: 0.060819164 | BF2: 0.86639739 | BG2: 0.49148433 | BH2: 0.80310751 | BI2: 0.3217747 | BJ2: 0.90942356 | BK2: 0.47597607 | BL2: 0.14266153 | BM2: 0.47535223 | BN2: 0.28329151 | BO2: 0.30603561 | BP2: 0.12372115 | BQ2: 0.18129173 | BR2: 0.0037563246 | BS2: 0.4318913 | BT2: 0.87782231 | BU2: 0.5057398 | BV2: 0.84388597 | BW2: 0.23224887 | BX2: 0.45071125 | BY2: 0.70022703 | BZ2: 0.47362872 | CA2: 0.26571207 | CB2: 0.15951176 | CC2: 0.9892445 | CD2: 0.46983714 | CE2: 0.5453564 | CF2: 0.75044983 | CG2: 0.50343381 | CH2: 0.49681864 | CI2: 0.89656914 | CJ2: 0.51549435 | CK2: 0.41894901 | CL2: 0.75613396 | CM2: 0.091308674 | CN2: 0.071811331 | CO2: 0.95654639 | CP2: 0.84213134 | CQ2: 0.25763406 | CR2: 0.33808668 | CS2: 0.071053631 | CT2: 0.13939165 | CU2: 0.94470212 | CV2: 0.60484422 | CW2: 0.7212224
A3: feature_01 | B3: 0.27459702 | C3: 0.37073133 | D3: 0.66988846 | E3: 0.12986359 | F3: 0.94483872 | G3: 0.67737206 | H3: 0.12362852 | I3: 0.027360411 | J3: 0.28819249 | K3: 0.2957189 | L3: 0.8291373 | M3: 0.10289321 | N3: 0.27582377 | O3: 0.58347118 | P3: 0.33625855 | Q3: 0.35445327 | R3: 0.39019933 | S3: 0.63001407 | T3: 0.40103198 | U3: 0.31620992 | V3: 0.1224265 | W3: 0.33388919 | X3: 0.60625392 | Y3: 0.23884857 | Z3: 0.48540571 | AA3: 0.73364478 | AB3: 0.34577698 | AC3: 0.34594894 | AD3: 0.89133575 | AE3: 0.657677 | AF3: 0.62729513 | AG3: 0.93500585 | AH3: 0.59074944 | AI3: 0.52943133 | AJ3: 0.54114855 | AK3: 0.45553222 | AL3: 0.78413069 | AM3: 0.76489278 | AN3: 0.23661747 | AO3: 0.93995527 | AP3: 0.091546605 | AQ3: 0.9902923 | AR3: 0.48204976 | AS3: 0.71522564 | AT3: 0.42901507 | AU3: 0.88070257 | AV3: 0.84944336 | AW3: 0.59519794 | AX3: 0.95553404 | AY3: 0.45255224 | AZ3: 0.54781088 | BA3: 0.24280248 | BB3: 0.32722203 | BC3: 0.44786753 | BD3: 0.53993311 | BE3: 0.6671553 | BF3: 0.3086395 | BG3: 0.94819902 | BH3: 0.29693496 | BI3: 0.53534172 | BJ3: 0.76214339 | BK3: 0.44744653 | BL3: 0.29893682 | BM3: 0.37579475 | BN3: 0.30410231 | BO3: 0.52136978 | BP3: 0.50062593 | BQ3: 0.49543788 | BR3: 0.2682421 | BS3: 0.50405794 | BT3: 0.41606003 | BU3: 0.27260898 | BV3: 0.23339469 | BW3: 0.87982961 | BX3: 0.119199 | BY3: 0.37975549 | BZ3: 0.87471091 | CA3: 0.77702475 | CB3: 0.77592391 | CC3: 0.80374726 | CD3: 0.63175809 | CE3: 0.018544428 | CF3: 0.2681219 | CG3: 0.95468095 | CH3: 0.94875878 | CI3: 0.34442577 | CJ3: 0.53363191 | CK3: 0.64347479 | CL3: 0.5445629 | CM3: 0.18855902 | CN3: 0.44876961 | CO3: 0.94562178 | CP3: 0.077204093 | CQ3: 0.75984785 | CR3: 0.78589289 | CS3: 0.44213164 | CT3: 0.90129674 | CU3: 0.80529428 | CV3: 0.6889679 | CW3: 0.91456197
A4: feature_02 | B4: 0.78042869 | C4: 0.9612421 | D4: 0.27167539 | E4: 0.94707735 | F4: 0.87128414 | G4: 0.64980513 | H4: 0.86882055 | I4: 0.17871908 | J4: 0.63090108 | K4: 0.64563781 | L4: 0.80002638 | M4: 0.92849139 | N4: 0.20162602 | O4: 0.5929602 | P4: 0.66374875 | Q4: 0.45794759 | R4: 0.25085504 | S4: 0.37745103 | T4: 0.84568094 | U4: 0.83276762 | V4: 0.21975895 | W4: 0.83997081 | X4: 0.18556748 | Y4: 0.65385346 | Z4: 0.82164741 | AA4: 0.84526634 | AB4: 0.49232381 | AC4: 0.20643995 | AD4: 0.78854446 | AE4: 0.30072808 | AF4: 0.016229082 | AG4: 0.784254 | AH4: 0.40880185 | AI4: 0.048452811 | AJ4: 0.083006648 | AK4: 0.33684689 | AL4: 0.12567888 | AM4: 0.098918537 | AN4: 0.33999204 | AO4: 0.78607551 | AP4: 0.59055328 | AQ4: 0.85897503 | AR4: 0.32807759 | AS4: 0.25813283 | AT4: 0.81436927 | AU4: 0.49884478 | AV4: 0.53708468 | AW4: 0.76541186 | AX4: 0.34871473 | AY4: 0.19000493 | AZ4: 0.032577993 | BA4: 0.24465815 | BB4: 0.012324778 | BC4: 0.71478755 | BD4: 0.46649257 | BE4: 0.96566172 | BF4: 0.59322734 | BG4: 0.48137148 | BH4: 0.016061835 | BI4: 0.82905727 | BJ4: 0.64996576 | BK4: 0.15377696 | BL4: 0.088856963 | BM4: 0.55321145 | BN4: 0.068113413 | BO4: 0.78142566 | BP4: 0.28627571 | BQ4: 0.74132917 | BR4: 0.82630511 | BS4: 0.39491885 | BT4: 0.86577914 | BU4: 0.76488422 | BV4: 0.26574807 | BW4: 0.10224034 | BX4: 0.57993772 | BY4: 0.44830845 | BZ4: 0.06769744 | CA4: 0.7290273 | CB4: 0.75563903 | CC4: 0.95598518 | CD4: 0.98300849 | CE4: 0.39429554 | CF4: 0.94133931 | CG4: 0.27958833 | CH4: 0.043174802 | CI4: 0.78859514 | CJ4: 0.010796357 | CK4: 0.64340023 | CL4: 0.441486 | CM4: 0.12379965 | CN4: 0.56565916 | CO4: 0.73562951 | CP4: 0.32734636 | CQ4: 0.89170012 | CR4: 0.24601338 | CS4: 0.75121106 | CT4: 0.93045149 | CU4: 0.43179802 | CV4: 0.75664389 | CW4: 0.025035977
A5: feature_03 | B5: 0.40153715 | C5: 0.58747925 | D5: 0.35297716 | E5: 0.96568025 | F5: 0.90069367 | G5: 0.24607067 | H5: 0.012995297 | I5: 0.76251718 | J5: 0.49052327 | K5: 0.93022693 | L5: 0.24962843 | M5: 0.88914985 | N5: 0.24096343 | O5: 0.8825795 | P5: 0.23412071 | Q5: 0.83344114 | R5: 0.35230032 | S5: 0.23790654 | T5: 0.50509358 | U5: 0.68752517 | V5: 0.066428084 | W5: 0.62063918 | X5: 0.84552112 | Y5: 0.51256305 | Z5: 0.9454687 | AA5: 0.67850972 | AB5: 0.94971101 | AC5: 0.96926096 | AD5: 0.62825164 | AE5: 0.30584342 | AF5: 0.81617274 | AG5: 0.62986489 | AH5: 0.84504545 | AI5: 0.099373318 | AJ5: 0.71101751 | AK5: 0.96825482 | AL5: 0.8971668 | AM5: 0.37562107 | AN5: 0.75359754 | AO5: 0.10478535 | AP5: 0.7372353 | AQ5: 0.22034962 | AR5: 0.20451685 | AS5: 0.18380854 | AT5: 0.49189859 | AU5: 0.21429879 | AV5: 0.64093084 | AW5: 0.86309396 | AX5: 0.66653047 | AY5: 0.46230437 | AZ5: 0.70144543 | BA5: 0.21089291 | BB5: 0.66592898 | BC5: 0.15681312 | BD5: 0.654348 | BE5: 0.76309963 | BF5: 0.041227246 | BG5: 0.06196062 | BH5: 0.039432475 | BI5: 0.62394596 | BJ5: 0.54224037 | BK5: 0.90661606 | BL5: 0.45398848 | BM5: 0.46927873 | BN5: 0.87598966 | BO5: 0.11693474 | BP5: 0.38768865 | BQ5: 0.63198481 | BR5: 0.99368438 | BS5: 0.47443909 | BT5: 0.3353169 | BU5: 0.90211893 | BV5: 0.65053198 | BW5: 0.46864273 | BX5: 0.27617397 | BY5: 0.25059424 | BZ5: 0.5224406 | CA5: 0.044514833 | CB5: 0.79198385 | CC5: 0.64541474 | CD5: 0.37568954 | CE5: 0.50358289 | CF5: 0.27770308 | CG5: 0.88016218 | CH5: 0.72965234 | CI5: 0.084732586 | CJ5: 0.81599381 | CK5: 0.33600852 | CL5: 0.52005189 | CM5: 0.29895997 | CN5: 0.35040579 | CO5: 0.60537734 | CP5: 0.01073974 | CQ5: 0.82080479 | CR5: 0.57015078 | CS5: 0.74993113 | CT5: 0.15759298 | CU5: 0.91329433 | CV5: 0.31266618 | CW5: 0.43111131
A6: feature_04 | B6: 0.79976312 | C6: 0.94418188 | D6: 0.69942319 | E6: 0.8068077 | F6: 0.41807994 | G6: 0.19882407 | H6: 0.73740437 | I6: 0.85402535 | J6: 0.78452077 | K6: 0.73110027 | L6: 0.91910679 | M6: 0.58920534 | N6: 0.028816943 | O6: 0.334461 | P6: 0.96271423 | Q6: 0.38385354 | R6: 0.76140991 | S6: 0.45050546 | T6: 0.0030542836 | U6: 0.79402037 | V6: 0.94565504 | W6: 0.13204351 | X6: 0.55091879 | Y6: 0.58316265 | Z6: 0.79010423 | AA6: 0.16670559 | AB6: 0.84187862 | AC6: 0.79522279 | AD6: 0.31589721 | AE6: 0.92165105 | AF6: 0.51616815 | AG6: 0.83074539 | AH6: 0.50846896 | AI6: 0.40783785 | AJ6: 0.95361635 | AK6: 0.23966046 | AL6: 0.10831337 | AM6: 0.23220885 | AN6: 0.34560518 | AO6: 0.47151316 | AP6: 0.66468174 | AQ6: 0.27140728 | AR6: 0.67107093 | AS6: 0.42657381 | AT6: 0.22442919 | AU6: 0.83002202 | AV6: 0.73082147 | AW6: 0.098724845 | AX6: 0.30016927 | AY6: 0.3816498 | AZ6: 0.58531817 | BA6: 0.25332093 | BB6: 0.86261618 | BC6: 0.36574742 | BD6: 0.1490053 | BE6: 0.56267444 | BF6: 0.28396815 | BG6: 0.31259419 | BH6: 0.81929751 | BI6: 0.10976567 | BJ6: 0.63499527 | BK6: 0.84587869 | BL6: 0.25505947 | BM6: 0.85476783 | BN6: 0.26725121 | BO6: 0.62186453 | BP6: 0.83743478 | BQ6: 0.12252373 | BR6: 0.43345243 | BS6: 0.55661271 | BT6: 0.88635471 | BU6: 0.51269496 | BV6: 0.19746264 | BW6: 0.50252728 | BX6: 0.029890603 | BY6: 0.92846834 | BZ6: 0.97427765 | CA6: 0.85317454 | CB6: 0.83047924 | CC6: 0.59416377 | CD6: 0.75266059 | CE6: 0.72530032 | CF6: 0.50870421 | CG6: 0.94980075 | CH6: 0.70376166 | CI6: 0.37527889 | CJ6: 0.25413454 | CK6: 0.051983971 | CL6: 0.22180461 | CM6: 0.72605283 | CN6: 0.83191673 | CO6: 0.61428145 | CP6: 0.84677422 | CQ6: 0.72149159 | CR6: 0.38206074 | CS6: 0.79779598 | CT6: 0.51959492 | CU6: 0.64830047 | CV6: 0.58199614 | CW6: 0.69874364
A7: feature_05 | B7: 0.44684522 | C7: 0.11701641 | D7: 0.17378828 | E7: 0.25408169 | F7: 0.010594784 | G7: 0.53347962 | H7: 0.19197591 | I7: 0.48226388 | J7: 0.018081159 | K7: 0.20694987 | L7: 0.89782779 | M7: 0.011596808 | N7: 0.67017643 | O7: 0.19529312 | P7: 0.14384641 | Q7: 0.33399316 | R7: 0.91760035 | S7: 0.29741563 | T7: 0.41037368 | U7: 0.27288941 | V7: 0.69121773 | W7: 0.16736852 | X7: 0.3351149 | Y7: 0.20278541 | Z7: 0.012028875 | AA7: 0.32056248 | AB7: 0.89683971 | AC7: 0.26096932 | AD7: 0.25443787 | AE7: 0.52286491 | AF7: 0.66393869 | AG7: 0.95764772 | AH7: 0.152984 | AI7: 0.4905205 | AJ7: 0.45467552 | AK7: 0.25085031 | AL7: 0.13449329 | AM7: 0.64721668 | AN7: 0.34349101 | AO7: 0.34667029 | AP7: 0.089913608 | AQ7: 0.69427386 | AR7: 0.10465846 | AS7: 0.22434531 | AT7: 0.74009955 | AU7: 0.46779777 | AV7: 0.53011485 | AW7: 0.033737962 | AX7: 0.67384099 | AY7: 0.714352 | AZ7: 0.67132722 | BA7: 0.38705816 | BB7: 0.33007111 | BC7: 0.38415126 | BD7: 0.28797069 | BE7: 0.31061498 | BF7: 0.46733843 | BG7: 0.37332022 | BH7: 0.20693492 | BI7: 0.51054246 | BJ7: 0.5286686 | BK7: 0.086314574 | BL7: 0.40142258 | BM7: 0.77643389 | BN7: 0.27313751 | BO7: 0.2489339 | BP7: 0.38425206 | BQ7: 0.053483571 | BR7: 0.061170974 | BS7: 0.85437477 | BT7: 0.49681324 | BU7: 0.59991939 | BV7: 0.13356252 | BW7: 0.27666286 | BX7: 0.23428349 | BY7: 0.25236929 | BZ7: 0.2260248 | CA7: 0.36535289 | CB7: 0.40610697 | CC7: 0.53229801 | CD7: 0.71108837 | CE7: 0.53894436 | CF7: 0.80690714 | CG7: 0.2068854 | CH7: 0.69938767 | CI7: 0.020750932 | CJ7: 0.12790348 | CK7: 0.10629207 | CL7: 0.52315056 | CM7: 0.28861672 | CN7: 0.2744123 | CO7: 0.82225356 | CP7: 0.16351187 | CQ7: 0.08585746 | CR7: 0.017142155 | CS7: 0.20288982 | CT7: 0.26384183 | CU7: 0.11676203 | CV7: 0.48506642 | CW7: 0.048849431
A8: feature_06 | B8: 0.4651809 | C8: 0.60686843 | D8: 0.62307419 | E8: 0.50537899 | F8: 0.6046311 | G8: 0.61443517 | H8: 0.61839543 | I8: 0.60691297 | J8: 0.71420306 | K8: 0.88182698 | L8: 0.53161595 | M8: 0.23791746 | N8: 0.097846003 | O8: 0.97635675 | P8: 0.55370995 | Q8: 0.56702594 | R8: 0.78713734 | S8: 0.24352174 | T8: 0.70458265 | U8: 0.3729594 | V8: 0.91431508 | W8: 0.99238254 | X8: 0.97467313 | Y8: 0.17402835 | Z8: 0.89928495 | AA8: 0.57867161 | AB8: 0.074522444 | AC8: 0.64003937 | AD8: 0.43892499 | AE8: 0.18072487 | AF8: 0.13358488 | AG8: 0.50758697 | AH8: 0.72280871 | AI8: 0.23920428 | AJ8: 0.51302498 | AK8: 0.63962329 | AL8: 0.93096312 | AM8: 0.295036 | AN8: 0.92547308 | AO8: 0.16805335 | AP8: 0.53832806 | AQ8: 0.88265469 | AR8: 0.95517073 | AS8: 0.18369527 | AT8: 0.89021445 | AU8: 0.60066612 | AV8: 0.73670438 | AW8: 0.36911415 | AX8: 0.42638666 | AY8: 0.75797043 | AZ8: 0.36635837 | BA8: 0.96443815 | BB8: 0.77896282 | BC8: 0.40479539 | BD8: 0.60502204 | BE8: 0.68744498 | BF8: 0.9726406 | BG8: 0.040346593 | BH8: 0.58605095 | BI8: 0.90239251 | BJ8: 0.1326469 | BK8: 0.71636277 | BL8: 0.9000198 | BM8: 0.70915146 | BN8: 0.51055294 | BO8: 0.58173528 | BP8: 0.27339072 | BQ8: 0.49035389 | BR8: 0.90883944 | BS8: 0.015054091 | BT8: 0.018141386 | BU8: 0.70260719 | BV8: 0.81778133 | BW8: 0.46460645 | BX8: 0.56039336 | BY8: 0.40944503 | BZ8: 0.99663672 | CA8: 0.094805654 | CB8: 0.10987013 | CC8: 0.6574887 | CD8: 0.76610093 | CE8: 0.0082324769 | CF8: 0.16088126 | CG8: 0.68997339 | CH8: 0.097641274 | CI8: 0.33789587 | CJ8: 0.19883248 | CK8: 0.99508199 | CL8: 0.75312625 | CM8: 0.85985845 | CN8: 0.21535823 | CO8: 0.8130613 | CP8: 0.3084434 | CQ8: 0.44372499 | CR8: 0.5043013 | CS8: 0.85497194 | CT8: 0.7499724 | CU8: 0.91462283 | CV8: 0.55055157 | CW8: 0.814814
A9: feature_07 | B9: 0.42522801 | C9: 0.76067873 | D9: 0.84765267 | E9: 0.88979982 | F9: 0.91890718 | G9: 0.40342313 | H9: 0.050232562 | I9: 0.40654916 | J9: 0.86950256 | K9: 0.59127042 | L9: 0.55918626 | M9: 0.89599306 | N9: 0.36851449 | O9: 0.6247036 | P9: 0.78603437 | Q9: 0.029089499 | R9: 0.79948213 | S9: 0.84493053 | T9: 0.89761249 | U9: 0.40413284 | V9: 0.30348241 | W9: 0.54516046 | X9: 0.88568381 | Y9: 0.86641553 | Z9: 0.019470216 | AA9: 0.94064853 | AB9: 0.43776484 | AC9: 0.055825063 | AD9: 0.091194823 | AE9: 0.0017494939 | AF9: 0.33074783 | AG9: 0.97374966 | AH9: 0.79947244 | AI9: 0.49135842 | AJ9: 0.24306135 | AK9: 0.85317989 | AL9: 0.51171434 | AM9: 0.4391065 | AN9: 0.035063454 | AO9: 0.16380859 | AP9: 0.20049521 | AQ9: 0.19634362 | AR9: 0.54927605 | AS9: 0.97850715 | AT9: 0.78655 | AU9: 0.4002827 | AV9: 0.19532267 | AW9: 0.80047273 | AX9: 0.8882648 | AY9: 0.8607725 | AZ9: 0.42971797 | BA9: 0.37495902 | BB9: 0.94649017 | BC9: 0.85821916 | BD9: 0.34039339 | BE9: 0.9843256 | BF9: 0.79420443 | BG9: 0.81367797 | BH9: 0.15865822 | BI9: 0.41255195 | BJ9: 0.93663094 | BK9: 0.31969133 | BL9: 0.93888551 | BM9: 0.79112201 | BN9: 0.23297389 | BO9: 0.192856 | BP9: 0.24322766 | BQ9: 0.82746021 | BR9: 0.69264274 | BS9: 0.92401277 | BT9: 0.68263793 | BU9: 0.067968833 | BV9: 0.67517772 | BW9: 0.65368229 | BX9: 0.67324953 | BY9: 0.89645632 | BZ9: 0.68356129 | CA9: 0.17900485 | CB9: 0.49000759 | CC9: 0.88013671 | CD9: 0.19072219 | CE9: 0.37895698 | CF9: 0.13044374 | CG9: 0.94721865 | CH9: 0.308804 | CI9: 0.98756693 | CJ9: 0.1339925 | CK9: 0.96179991 | CL9: 0.84506234 | CM9: 0.78441545 | CN9: 0.6187861 | CO9: 0.73636022 | CP9: 0.26309712 | CQ9: 0.79377571 | CR9: 0.72344515 | CS9: 0.1912758 | CT9: 0.4533825 | CU9: 0.82316904 | CV9: 0.092361923 | CW9: 0.37734011
A10: feature_08 | B10: 0.26528154 | C10: 0.82390002 | D10: 0.69355088 | E10: 0.042483226 | F10: 0.73056947 | G10: 0.71163036 | H10: 0.8974848 | I10: 0.4201504 | J10: 0.96793311 | K10: 0.74872653 | L10: 0.91263767 | M10: 0.62753118 | N10: 0.83187682 | O10: 0.21067892 | P10: 0.58645631 | Q10: 0.97967735 | R10: 0.38260111 | S10: 0.31418545 | T10: 0.96682455 | U10: 0.16018844 | V10: 0.033689222 | W10: 0.92509294 | X10: 0.0070153518 | Y10: 0.56665347 | Z10: 0.44676954 | AA10: 0.65558283 | AB10: 0.00073940543 | AC10: 0.77597828 | AD10: 0.61963581 | AE10: 0.16196049 | AF10: 0.15608843 | AG10: 0.6471417 | AH10: 0.43073251 | AI10: 0.18798646 | AJ10: 0.76259045 | AK10: 0.019856876 | AL10: 0.096460561 | AM10: 0.83485347 | AN10: 0.028339762 | AO10: 0.92347967 | AP10: 0.84535903 | AQ10: 0.64228159 | AR10: 0.75584233 | AS10: 0.64198108 | AT10: 0.98869221 | AU10: 0.32040295 | AV10: 0.20163855 | AW10: 0.46097723 | AX10: 0.95981734 | AY10: 0.77854341 | AZ10: 0.89020032 | BA10: 0.82773166 | BB10: 0.43677995 | BC10: 0.03847622 | BD10: 0.16135604 | BE10: 0.64457087 | BF10: 0.15490374 | BG10: 0.037510509 | BH10: 0.58254524 | BI10: 0.77524071 | BJ10: 0.76051448 | BK10: 0.99810154 | BL10: 0.53972449 | BM10: 0.30339312 | BN10: 0.94893573 | BO10: 0.8449758 | BP10: 0.052946533 | BQ10: 0.62188573 | BR10: 0.90625829 | BS10: 0.4294121 | BT10: 0.58677277 | BU10: 0.051759608 | BV10: 0.99988887 | BW10: 0.99335537 | BX10: 0.61580936 | BY10: 0.0897001 | BZ10: 0.77417916 | CA10: 0.090199747 | CB10: 0.6187838 | CC10: 0.22165832 | CD10: 0.63937564 | CE10: 0.92545147 | CF10: 0.89864804 | CG10: 0.071082883 | CH10: 0.46823059 | CI10: 0.33694017 | CJ10: 0.44212023 | CK10: 0.83651145 | CL10: 0.44355411 | CM10: 0.33803927 | CN10: 0.50863132 | CO10: 0.49442804 | CP10: 0.58118981 | CQ10: 0.88966509 | CR10: 0.65834279 | CS10: 0.80386023 | CT10: 0.89511145 | CU10: 0.0017375205 | CV10: 0.4316506 | CW10: 0.17631597
A11: feature_09 | B11: 0.48597387 | C11: 0.74839635 | D11: 0.45268193 | E11: 0.16727412 | F11: 0.5207187 | G11: 0.18408112 | H11: 0.21415763 | I11: 0.27098313 | J11: 0.43916326 | K11: 0.68426542 | L11: 0.38019384 | M11: 0.57050364 | N11: 0.84262542 | O11: 0.52224092 | P11: 0.94308877 | Q11: 0.81952134 | R11: 0.30246815 | S11: 0.87156489 | T11: 0.095439416 | U11: 0.27244651 | V11: 0.35976687 | W11: 0.0027823998 | X11: 0.78441994 | Y11: 0.98046428 | Z11: 0.17554291 | AA11: 0.87196101 | AB11: 0.070494795 | AC11: 0.18247286 | AD11: 0.10701799 | AE11: 0.49351011 | AF11: 0.31375965 | AG11: 0.67173619 | AH11: 0.20955439 | AI11: 0.062751469 | AJ11: 0.35770573 | AK11: 0.16857051 | AL11: 0.443003 | AM11: 0.49194971 | AN11: 0.12620661 | AO11: 0.29899415 | AP11: 0.56979789 | AQ11: 0.11822978 | AR11: 0.28720056 | AS11: 0.70027389 | AT11: 0.85480729 | AU11: 0.23673742 | AV11: 0.020536554 | AW11: 0.15641807 | AX11: 0.74049567 | AY11: 0.45676725 | AZ11: 0.11675552 | BA11: 0.58599613 | BB11: 0.24443253 | BC11: 0.21113383 | BD11: 0.055846739 | BE11: 0.60258653 | BF11: 0.20758429 | BG11: 0.75734731 | BH11: 0.92108661 | BI11: 0.49673579 | BJ11: 0.33160453 | BK11: 0.50199538 | BL11: 0.24772622 | BM11: 0.21648046 | BN11: 0.67725091 | BO11: 0.083467513 | BP11: 0.095086895 | BQ11: 0.21266334 | BR11: 0.0037567411 | BS11: 0.47373461 | BT11: 0.89644776 | BU11: 0.51787875 | BV11: 0.86534245 | BW11: 0.12593475 | BX11: 0.51102371 | BY11: 0.12306658 | BZ11: 0.3082881 | CA11: 0.019861573 | CB11: 0.074973662 | CC11: 0.55086247 | CD11: 0.49150612 | CE11: 0.95769232 | CF11: 0.89167011 | CG11: 0.19779118 | CH11: 0.98268271 | CI11: 0.036323434 | CJ11: 0.50418044 | CK11: 0.10789648 | CL11: 0.56014434 | CM11: 0.77336239 | CN11: 0.79067819 | CO11: 0.30473102 | CP11: 0.093212369 | CQ11: 0.085070136 | CR11: 0.055782845 | CS11: 0.26977694 | CT11: 0.42559395 | CU11: 0.78522116 | CV11: 0.50253899 | CW11: 0.65865451
A12: feature_10 | B12: 0.72380161 | C12: 0.32110336 | D12: 0.38713395 | E12: 0.057314798 | F12: 0.034480395 | G12: 0.016569401 | H12: 0.54021323 | I12: 0.31821149 | J12: 0.058248778 | K12: 0.37749591 | L12: 0.44487841 | M12: 0.5183292 | N12: 0.85787636 | O12: 0.61532836 | P12: 0.62791486 | Q12: 0.18987963 | R12: 0.92896651 | S12: 0.72577655 | T12: 0.81502172 | U12: 0.32773948 | V12: 0.31993425 | W12: 0.22730564 | X12: 0.84335318 | Y12: 0.61216999 | Z12: 0.77024467 | AA12: 0.71955272 | AB12: 0.88141256 | AC12: 0.71011827 | AD12: 0.96026854 | AE12: 0.43946134 | AF12: 0.69182241 | AG12: 0.86180507 | AH12: 0.36497011 | AI12: 0.64004545 | AJ12: 0.40341398 | AK12: 0.82127251 | AL12: 0.97752563 | AM12: 0.42863816 | AN12: 0.9265885 | AO12: 0.64793178 | AP12: 0.48626716 | AQ12: 0.63331949 | AR12: 0.26784137 | AS12: 0.27954595 | AT12: 0.24562435 | AU12: 0.96985815 | AV12: 0.62523407 | AW12: 0.10224635 | AX12: 0.80770805 | AY12: 0.32380788 | AZ12: 0.9898887 | BA12: 0.77329722 | BB12: 0.14066624 | BC12: 0.54431614 | BD12: 0.62484444 | BE12: 0.73486861 | BF12: 0.047999702 | BG12: 0.78720161 | BH12: 0.80684403 | BI12: 0.93285574 | BJ12: 0.42665232 | BK12: 0.03272169 | BL12: 0.17990012 | BM12: 0.67320268 | BN12: 0.72101507 | BO12: 0.12785853 | BP12: 0.53862717 | BQ12: 0.056772305 | BR12: 0.34526435 | BS12: 0.21766845 | BT12: 0.28915503 | BU12: 0.38835469 | BV12: 0.046463276 | BW12: 0.10281138 | BX12: 0.48414727 | BY12: 0.65172036 | BZ12: 0.5881305 | CA12: 0.45070858 | CB12: 0.30970754 | CC12: 0.37822951 | CD12: 0.61157904 | CE12: 0.63531792 | CF12: 0.8310442 | CG12: 0.59768858 | CH12: 0.45490874 | CI12: 0.68462584 | CJ12: 0.1807081 | CK12: 0.51447427 | CL12: 0.16829784 | CM12: 0.4924619 | CN12: 0.200867 | CO12: 0.32863754 | CP12: 0.011874991 | CQ12: 0.14592795 | CR12: 0.8866039 | CS12: 0.52739984 | CT12: 0.43544179 | CU12: 0.9064454 | CV12: 0.72762684 | CW12: 0.58892107
A13: feature_11 | B13: 0.61897311 | C13: 0.14814349 | D13: 0.29809798 | E13: 0.44958505 | F13: 0.41798379 | G13: 0.87577649 | H13: 0.12870165 | I13: 0.2188997 | J13: 0.32078838 | K13: 0.60170318 | L13: 0.98222236 | M13: 0.2756459 | N13: 0.52048141 | O13: 0.46566156 | P13: 0.085154218 | Q13: 0.57823086 | R13: 0.2479895 | S13: 0.81604313 | T13: 0.19313849 | U13: 0.18403953 | V13: 0.50063727 | W13: 0.43123204 | X13: 0.0079776676 | Y13: 0.61484245 | Z13: 0.23280532 | AA13: 0.29657391 | AB13: 0.27274205 | AC13: 0.011514671 | AD13: 0.37604066 | AE13: 0.67442492 | AF13: 0.19162269 | AG13: 0.10862989 | AH13: 0.20064655 | AI13: 0.58873387 | AJ13: 0.37319916 | AK13: 0.28802835 | AL13: 0.0078172459 | AM13: 0.12265183 | AN13: 0.14864918 | AO13: 0.29416153 | AP13: 0.97878545 | AQ13: 0.12739076 | AR13: 0.45673727 | AS13: 0.56887278 | AT13: 0.60289706 | AU13: 0.012802635 | AV13: 0.26798894 | AW13: 0.6295043 | AX13: 0.52851815 | AY13: 0.22836493 | AZ13: 0.50985943 | BA13: 0.15829812 | BB13: 0.13765414 | BC13: 0.85898332 | BD13: 0.37829154 | BE13: 0.68196321 | BF13: 0.65370224 | BG13: 0.62336704 | BH13: 0.65913546 | BI13: 0.89596587 | BJ13: 0.93709938 | BK13: 0.63729679 | BL13: 0.19234358 | BM13: 0.14908272 | BN13: 0.5453105 | BO13: 0.1422418 | BP13: 0.55279858 | BQ13: 0.55874903 | BR13: 0.030737919 | BS13: 0.81727905 | BT13: 0.089887665 | BU13: 0.32050992 | BV13: 0.61337301 | BW13: 0.45878616 | BX13: 0.18024007 | BY13: 0.0023591115 | BZ13: 0.057671677 | CA13: 0.75749874 | CB13: 0.59042311 | CC13: 0.99363939 | CD13: 0.5857823 | CE13: 0.79024375 | CF13: 0.86443466 | CG13: 0.45376928 | CH13: 0.52517352 | CI13: 0.85409221 | CJ13: 0.51697986 | CK13: 0.27337129 | CL13: 0.60502183 | CM13: 0.097090001 | CN13: 0.9442185 | CO13: 0.97034585 | CP13: 0.70260763 | CQ13: 0.075145717 | CR13: 0.84184207 | CS13: 0.29957845 | CT13: 0.70671345 | CU13: 0.44664189 | CV13: 0.69931251 | CW13: 0.10237763
... A32: threshold | B32: 0.5006197 | C32: 0.38950674 | D32: 0.36464945 | E32: 0.31817784 | F32: 0.54530236 | G32: 0.32377361 | H32: 0.38457595 | I32: 0.63727887 | J32: 0.52832703 | K32: 0.58079263 | L32: 0.59553786 | M32: 0.4430685 | N32: 0.1607699 | O32: 0.65708947 | P32: 0.42500547 | Q32: 0.16449605 | R32: 0.33128747 | S32: 0.60088561 | T32: 0.55759621 | U32: 0.55550354 | V32: 0.40175373 | W32: 0.10877828 | X32: 0.41282194 | Y32: 0.73685839 | Z32: 0.34980009 | AA32: 0.69471188 | AB32: 0.49811747 | AC32: 0.40428151 | AD32: 0.58419558 | AE32: 0.59194525 | AF32: 0.61033427 | AG32: 0.37739489 | AH32: 0.43826671 | AI32: 0.28842852 | AJ32: 0.63191175 | AK32: 0.59048273 | AL32: 0.65290185 | AM32: 0.33305181 | AN32: 0.49359938 | AO32: 0.57749678 | AP32: 0.44990072 | AQ32: 0.47228034 | AR32: 0.31079065 | AS32: 0.63321948 | AT32: 0.55549585 | AU32: 0.62560059 | AV32: 0.52113665 | AW32: 0.59196871 | AX32: 0.2519382 | AY32: 0.4990294 | AZ32: 0.563507 | BA32: 0.65915624 | BB32: 0.47736418 | BC32: 0.54094299 | BD32: 0.56648893 | BE32: 0.49924496 | BF32: 0.26859774 | BG32: 0.51275 | BH32: 0.18030547 | BI32: 0.53442439 | BJ32: 0.40648335 | BK32: 0.66600709 | BL32: 0.32517699 | BM32: 0.21595909 | BN32: 0.55517961 | BO32: 0.57334068 | BP32: 0.2813865 | BQ32: 0.5648224 | BR32: 0.56778872 | BS32: 0.48956353 | BT32: 0.15308413 | BU32: 0.42659389 | BV32: 0.30252725 | BW32: 0.32832283 | BX32: 0.43637659 | BY32: 0.41338737 | BZ32: 0.41822498 | CA32: 0.4305538 | CB32: 0.43088044 | CC32: 0.43452934 | CD32: 0.33121637 | CE32: 0.1453188 | CF32: 0.47515595 | CG32: 0.26899768 | CH32: 0.24155519 | CI32: 0.6722474 | CJ32: 0.57577634 | CK32: 0.58651575 | CL32: 0.46495691 | CM32: 0.48251621 | CN32: 0.45785472 | CO32: 0.41229112 | CP32: 0.58000648 | CQ32: 0.60559177 | CR32: 0.2603877 | CS32: 0.49811651 | CT32: 0.496098 | CU32: 0.49778486 | CV32: 0.6358396 | CW32: 0.33380133

Sheet Per Run Active Features
A1: Feature | B1: Feature Name | C1: run 1 | D1: run 2 | E1: run 3 | F1: run 4 | G1: run 5 | H1: run 6 | I1: run 7 | J1: run 8 | K1: run 9 | L1: run 10 | M1: run 11 | N1: run 12 | O1: run 13 | P1: run 14 | Q1: run 15 | R1: run 16 | S1: run 17 | T1: run 18 | U1: run 19 | V1: run 20 | W1: run 21 | X1: run 22 | Y1: run 23 | Z1: run 24 | AA1: run 25 | AB1: run 26 | AC1: run 27 | AD1: run 28 | AE1: run 29 | AF1: run 30 | AG1: run 31 | AH1: run 32 | AI1: run 33 | AJ1: run 34 | AK1: run 35 | AL1: run 36 | AM1: run 37 | AN1: run 38 | AO1: run 39 | AP1: run 40 | AQ1: run 41 | AR1: run 42 | AS1: run 43 | AT1: run 44 | AU1: run 45 | AV1: run 46 | AW1: run 47 | AX1: run 48 | AY1: run 49 | AZ1: run 50 | BA1: run 51 | BB1: run 52 | BC1: run 53 | BD1: run 54 | BE1: run 55 | BF1: run 56 | BG1: run 57 | BH1: run 58 | BI1: run 59 | BJ1: run 60 | BK1: run 61 | BL1: run 62 | BM1: run 63 | BN1: run 64 | BO1: run 65 | BP1: run 66 | BQ1: run 67 | BR1: run 68 | BS1: run 69 | BT1: run 70 | BU1: run 71 | BV1: run 72 | BW1: run 73 | BX1: run 74 | BY1: run 75 | BZ1: run 76 | CA1: run 77 | CB1: run 78 | CC1: run 79 | CD1: run 80 | CE1: run 81 | CF1: run 82 | CG1: run 83 | CH1: run 84 | CI1: run 85 | CJ1: run 86 | CK1: run 87 | CL1: run 88 | CM1: run 89 | CN1: run 90 | CO1: run 91 | CP1: run 92 | CQ1: run 93 | CR1: run 94 | CS1: run 95 | CT1: run 96 | CU1: run 97 | CV1: run 98 | CW1: run 99 | CX1: run 100 | CY1: Feature | CZ1: Feature Name | DA1: Frequency
A2: feature_00 | B2: radius1 | C2: ='Base Result'!B2 -> 0.72823858 | D2: ='Base Result'!C2 -> 0.034302115 | E2: ='Base Result'!D2 -> 0.35418245 | F2: ='Base Result'!E2 -> 0.56817993 | G2: ='Base Result'!F2 -> 0.27568886 | H2: ='Base Result'!G2 -> 0.21853824 | I2: ='Base Result'!H2 -> 0.34487651 | J2: ='Base Result'!I2 -> 0.86488439 | ... CX2: ='Base Result'!CW2 -> 0.7212224 | CY2: feature_00 | CZ2: radius1 | DA2: {=SUMPRODUCT((C2:CX2>C$32:CX$32)*1)} -> 47
A3: feature_01 | B3: texture1 | C3: ='Base Result'!B3 -> 0.27459702 | D3: ='Base Result'!C3 -> 0.37073133 | E3: ='Base Result'!D3 -> 0.66988846 | F3: ='Base Result'!E3 -> 0.12986359 | G3: ='Base Result'!F3 -> 0.94483872 | H3: ='Base Result'!G3 -> 0.67737206 | I3: ='Base Result'!H3 -> 0.12362852 | J3: ='Base Result'!I3 -> 0.027360411 | ... CX3: ='Base Result'!CW3 -> 0.91456197 | CY3: feature_01 | CZ3: texture1 | DA3: {=SUMPRODUCT((C3:CX3>C$32:CX$32)*1)} -> 55
A4: feature_02 | B4: perimeter1 | C4: ='Base Result'!B4 -> 0.78042869 | D4: ='Base Result'!C4 -> 0.9612421 | E4: ='Base Result'!D4 -> 0.27167539 | F4: ='Base Result'!E4 -> 0.94707735 | G4: ='Base Result'!F4 -> 0.87128414 | H4: ='Base Result'!G4 -> 0.64980513 | I4: ='Base Result'!H4 -> 0.86882055 | J4: ='Base Result'!I4 -> 0.17871908 | ... CX4: ='Base Result'!CW4 -> 0.025035977 | CY4: feature_02 | CZ4: perimeter1 | DA4: {=SUMPRODUCT((C4:CX4>C$32:CX$32)*1)} -> 57
A5: feature_03 | B5: area1 | C5: ='Base Result'!B5 -> 0.40153715 | D5: ='Base Result'!C5 -> 0.58747925 | E5: ='Base Result'!D5 -> 0.35297716 | F5: ='Base Result'!E5 -> 0.96568025 | G5: ='Base Result'!F5 -> 0.90069367 | H5: ='Base Result'!G5 -> 0.24607067 | I5: ='Base Result'!H5 -> 0.012995297 | J5: ='Base Result'!I5 -> 0.76251718 | ... CX5: ='Base Result'!CW5 -> 0.43111131 | CY5: feature_03 | CZ5: area1 | DA5: {=SUMPRODUCT((C5:CX5>C$32:CX$32)*1)} -> 61
A6: feature_04 | B6: smoothness1 | C6: ='Base Result'!B6 -> 0.79976312 | D6: ='Base Result'!C6 -> 0.94418188 | E6: ='Base Result'!D6 -> 0.69942319 | F6: ='Base Result'!E6 -> 0.8068077 | G6: ='Base Result'!F6 -> 0.41807994 | H6: ='Base Result'!G6 -> 0.19882407 | I6: ='Base Result'!H6 -> 0.73740437 | J6: ='Base Result'!I6 -> 0.85402535 | ... CX6: ='Base Result'!CW6 -> 0.69874364 | CY6: feature_04 | CZ6: smoothness1 | DA6: {=SUMPRODUCT((C6:CX6>C$32:CX$32)*1)} -> 64
A7: feature_05 | B7: compactness1 | C7: ='Base Result'!B7 -> 0.44684522 | D7: ='Base Result'!C7 -> 0.11701641 | E7: ='Base Result'!D7 -> 0.17378828 | F7: ='Base Result'!E7 -> 0.25408169 | G7: ='Base Result'!F7 -> 0.010594784 | H7: ='Base Result'!G7 -> 0.53347962 | I7: ='Base Result'!H7 -> 0.19197591 | J7: ='Base Result'!I7 -> 0.48226388 | ... CX7: ='Base Result'!CW7 -> 0.048849431 | CY7: feature_05 | CZ7: compactness1 | DA7: {=SUMPRODUCT((C7:CX7>C$32:CX$32)*1)} -> 34
A8: feature_06 | B8: concavity1 | C8: ='Base Result'!B8 -> 0.4651809 | D8: ='Base Result'!C8 -> 0.60686843 | E8: ='Base Result'!D8 -> 0.62307419 | F8: ='Base Result'!E8 -> 0.50537899 | G8: ='Base Result'!F8 -> 0.6046311 | H8: ='Base Result'!G8 -> 0.61443517 | I8: ='Base Result'!H8 -> 0.61839543 | J8: ='Base Result'!I8 -> 0.60691297 | ... CX8: ='Base Result'!CW8 -> 0.814814 | CY8: feature_06 | CZ8: concavity1 | DA8: {=SUMPRODUCT((C8:CX8>C$32:CX$32)*1)} -> 59
A9: feature_07 | B9: concave_points1 | C9: ='Base Result'!B9 -> 0.42522801 | D9: ='Base Result'!C9 -> 0.76067873 | E9: ='Base Result'!D9 -> 0.84765267 | F9: ='Base Result'!E9 -> 0.88979982 | G9: ='Base Result'!F9 -> 0.91890718 | H9: ='Base Result'!G9 -> 0.40342313 | I9: ='Base Result'!H9 -> 0.050232562 | J9: ='Base Result'!I9 -> 0.40654916 | ... CX9: ='Base Result'!CW9 -> 0.37734011 | CY9: feature_07 | CZ9: concave_points1 | DA9: {=SUMPRODUCT((C9:CX9>C$32:CX$32)*1)} -> 60
A10: feature_08 | B10: symmetry1 | C10: ='Base Result'!B10 -> 0.26528154 | D10: ='Base Result'!C10 -> 0.82390002 | E10: ='Base Result'!D10 -> 0.69355088 | F10: ='Base Result'!E10 -> 0.042483226 | G10: ='Base Result'!F10 -> 0.73056947 | H10: ='Base Result'!G10 -> 0.71163036 | I10: ='Base Result'!H10 -> 0.8974848 | J10: ='Base Result'!I10 -> 0.4201504 | ... CX10: ='Base Result'!CW10 -> 0.17631597 | CY10: feature_08 | CZ10: symmetry1 | DA10: {=SUMPRODUCT((C10:CX10>C$32:CX$32)*1)} -> 60
A11: feature_09 | B11: fractal_dimension1 | C11: ='Base Result'!B11 -> 0.48597387 | D11: ='Base Result'!C11 -> 0.74839635 | E11: ='Base Result'!D11 -> 0.45268193 | F11: ='Base Result'!E11 -> 0.16727412 | G11: ='Base Result'!F11 -> 0.5207187 | H11: ='Base Result'!G11 -> 0.18408112 | I11: ='Base Result'!H11 -> 0.21415763 | J11: ='Base Result'!I11 -> 0.27098313 | ... CX11: ='Base Result'!CW11 -> 0.65865451 | CY11: feature_09 | CZ11: fractal_dimension1 | DA11: {=SUMPRODUCT((C11:CX11>C$32:CX$32)*1)} -> 36
A12: feature_10 | B12: radius2 | C12: ='Base Result'!B12 -> 0.72380161 | D12: ='Base Result'!C12 -> 0.32110336 | E12: ='Base Result'!D12 -> 0.38713395 | F12: ='Base Result'!E12 -> 0.057314798 | G12: ='Base Result'!F12 -> 0.034480395 | H12: ='Base Result'!G12 -> 0.016569401 | I12: ='Base Result'!H12 -> 0.54021323 | J12: ='Base Result'!I12 -> 0.31821149 | ... CX12: ='Base Result'!CW12 -> 0.58892107 | CY12: feature_10 | CZ12: radius2 | DA12: {=SUMPRODUCT((C12:CX12>C$32:CX$32)*1)} -> 59
A13: feature_11 | B13: texture2 | C13: ='Base Result'!B13 -> 0.61897311 | D13: ='Base Result'!C13 -> 0.14814349 | E13: ='Base Result'!D13 -> 0.29809798 | F13: ='Base Result'!E13 -> 0.44958505 | G13: ='Base Result'!F13 -> 0.41798379 | H13: ='Base Result'!G13 -> 0.87577649 | I13: ='Base Result'!H13 -> 0.12870165 | J13: ='Base Result'!I13 -> 0.2188997 | ... CX13: ='Base Result'!CW13 -> 0.10237763 | CY13: feature_11 | CZ13: texture2 | DA13: {=SUMPRODUCT((C13:CX13>C$32:CX$32)*1)} -> 44
... A31: feature_29 | B31: fractal_dimension3 | C31: ='Base Result'!B31 -> 0.38959726 | D31: ='Base Result'!C31 -> 0.90512487 | E31: ='Base Result'!D31 -> 0.31562149 | F31: ='Base Result'!E31 -> 0.87713344 | G31: ='Base Result'!F31 -> 0.20527957 | H31: ='Base Result'!G31 -> 0.78950686 | I31: ='Base Result'!H31 -> 0.83562534 | J31: ='Base Result'!I31 -> 0.93981151 | ... CX31: ='Base Result'!CW31 -> 0.86198773 | CY31: feature_29 | CZ31: fractal_dimension3 | DA31: {=SUMPRODUCT((C31:CX31>C$32:CX$32)*1)} -> 48
A32: threshold | C32: ='Base Result'!B32 -> 0.5006197 | D32: ='Base Result'!C32 -> 0.38950674 | E32: ='Base Result'!D32 -> 0.36464945 | F32: ='Base Result'!E32 -> 0.31817784 | G32: ='Base Result'!F32 -> 0.54530236 | H32: ='Base Result'!G32 -> 0.32377361 | I32: ='Base Result'!H32 -> 0.38457595 | J32: ='Base Result'!I32 -> 0.63727887 | ... CX32: ='Base Result'!CW32 -> 0.33380133 | CY32: threshold

Sheet Active by Group Stat
A1: Feature | B1: run 1 | C1: run 2 | D1: run 3 | E1: run 4 | F1: run 5 | G1: run 6 | H1: run 7 | I1: run 8 | J1: run 9 | K1: run 10 | L1: run 11 | M1: run 12 | N1: run 13 | O1: run 14 | P1: run 15 | Q1: run 16 | R1: run 17 | S1: run 18 | T1: run 19 | U1: run 20 | V1: run 21 | W1: run 22 | X1: run 23 | Y1: run 24 | Z1: run 25 | AA1: run 26 | AB1: run 27 | AC1: run 28 | AD1: run 29 | AE1: run 30 | AF1: run 31 | AG1: run 32 | AH1: run 33 | AI1: run 34 | AJ1: run 35 | AK1: run 36 | AL1: run 37 | AM1: run 38 | AN1: run 39 | AO1: run 40 | AP1: run 41 | AQ1: run 42 | AR1: run 43 | AS1: run 44 | AT1: run 45 | AU1: run 46 | AV1: run 47 | AW1: run 48 | AX1: run 49 | AY1: run 50 | AZ1: run 51 | BA1: run 52 | BB1: run 53 | BC1: run 54 | BD1: run 55 | BE1: run 56 | BF1: run 57 | BG1: run 58 | BH1: run 59 | BI1: run 60 | BJ1: run 61 | BK1: run 62 | BL1: run 63 | BM1: run 64 | BN1: run 65 | BO1: run 66 | BP1: run 67 | BQ1: run 68 | BR1: run 69 | BS1: run 70 | BT1: run 71 | BU1: run 72 | BV1: run 73 | BW1: run 74 | BX1: run 75 | BY1: run 76 | BZ1: run 77 | CA1: run 78 | CB1: run 79 | CC1: run 80 | CD1: run 81 | CE1: run 82 | CF1: run 83 | CG1: run 84 | CH1: run 85 | CI1: run 86 | CJ1: run 87 | CK1: run 88 | CL1: run 89 | CM1: run 90 | CN1: run 91 | CO1: run 92 | CP1: run 93 | CQ1: run 94 | CR1: run 95 | CS1: run 96 | CT1: run 97 | CU1: run 98 | CV1: run 99 | CW1: run 100 | CY1: Feature | CZ1: Feature Name | DA1: Active Frequency | DB1: Active by Average | DC1: Active by Median | DD1: Std. Dev
A2: feature_21 | B2: ='Base Result'!B23 -> 0.6925887 | C2: ='Base Result'!C23 -> 0.94290262 | D2: ='Base Result'!D23 -> 0.94843985 | E2: ='Base Result'!E23 -> 0.47446497 | F2: ='Base Result'!F23 -> 0.37881828 | G2: ='Base Result'!G23 -> 0.42725701 | H2: ='Base Result'!H23 -> 0.73725249 | I2: ='Base Result'!I23 -> 0.75052897 | ... CW2: ='Base Result'!CW23 -> 0.34030331 | CY2: feature_21 | CZ2: texture3 | DA2: {=SUMPRODUCT((B2:CW2>B$32:CW$32)*1)} -> 81 | DB2: =AVERAGE(B2:CW2) -> 0.6221955 | DC2: =MEDIAN(B2:CW2) -> 0.69272692 | DD2: =_xlfn.STDEV.S(B2:CW2) -> 0.27015734
A3: feature_20 | B3: ='Base Result'!B22 -> 0.77131354 | C3: ='Base Result'!C22 -> 0.71836762 | D3: ='Base Result'!D22 -> 0.97585088 | E3: ='Base Result'!E22 -> 0.32142288 | F3: ='Base Result'!F22 -> 0.66989058 | G3: ='Base Result'!G22 -> 0.62386859 | H3: ='Base Result'!H22 -> 0.77109693 | I3: ='Base Result'!I22 -> 0.63741622 | ... CW3: ='Base Result'!CW22 -> 0.71477143 | CY3: feature_20 | CZ3: radius3 | DA3: {=SUMPRODUCT((B3:CW3>B$32:CW$32)*1)} -> 79 | DB3: =AVERAGE(B3:CW3) -> 0.63210322 | DC3: =MEDIAN(B3:CW3) -> 0.68843096 | DD3: =_xlfn.STDEV.S(B3:CW3) -> 0.25783239
A4: feature_22 | B4: ='Base Result'!B24 -> 0.59752588 | C4: ='Base Result'!C24 -> 0.044715398 | D4: ='Base Result'!D24 -> 0.45645694 | E4: ='Base Result'!E24 -> 0.25978163 | F4: ='Base Result'!F24 -> 0.74637428 | G4: ='Base Result'!G24 -> 0.97855096 | H4: ='Base Result'!H24 -> 0.42121793 | I4: ='Base Result'!I24 -> 0.95251027 | ... CW4: ='Base Result'!CW24 -> 0.67461331 | CY4: feature_22 | CZ4: perimeter3 | DA4: {=SUMPRODUCT((B4:CW4>B$32:CW$32)*1)} -> 66 | DB4: =AVERAGE(B4:CW4) -> 0.56483862 | DC4: =MEDIAN(B4:CW4) -> 0.63105335 | DD4: =_xlfn.STDEV.S(B4:CW4) -> 0.28624668
A5: feature_24 | B5: ='Base Result'!B26 -> 0.79381825 | C5: ='Base Result'!C26 -> 0.43613129 | D5: ='Base Result'!D26 -> 0.50405503 | E5: ='Base Result'!E26 -> 0.56246958 | F5: ='Base Result'!F26 -> 0.73006412 | G5: ='Base Result'!G26 -> 0.8036227 | H5: ='Base Result'!H26 -> 0.49670218 | I5: ='Base Result'!I26 -> 0.68216754 | ... CW5: ='Base Result'!CW26 -> 0.6721666 | CY5: feature_24 | CZ5: smoothness3 | DA5: {=SUMPRODUCT((B5:CW5>B$32:CW$32)*1)} -> 66 | DB5: =AVERAGE(B5:CW5) -> 0.54780976 | DC5: =MEDIAN(B5:CW5) -> 0.54836124 | DD5: =_xlfn.STDEV.S(B5:CW5) -> 0.26988011
A6: feature_26 | B6: ='Base Result'!B28 -> 0.83655898 | C6: ='Base Result'!C28 -> 0.66051627 | D6: ='Base Result'!D28 -> 0.28326146 | E6: ='Base Result'!E28 -> 0.89091967 | F6: ='Base Result'!F28 -> 0.87536203 | G6: ='Base Result'!G28 -> 0.17100752 | H6: ='Base Result'!H28 -> 0.79924613 | I6: ='Base Result'!I28 -> 0.28610268 | ... CW6: ='Base Result'!CW28 -> 0.14772382 | CY6: feature_26 | CZ6: concavity3 | DA6: {=SUMPRODUCT((B6:CW6>B$32:CW$32)*1)} -> 66 | DB6: =AVERAGE(B6:CW6) -> 0.56948263 | DC6: =MEDIAN(B6:CW6) -> 0.58874544 | DD6: =_xlfn.STDEV.S(B6:CW6) -> 0.27102497
A7: feature_23 | B7: ='Base Result'!B25 -> 0.4491996 | C7: ='Base Result'!C25 -> 0.61936207 | D7: ='Base Result'!D25 -> 0.52476925 | E7: ='Base Result'!E25 -> 0.79533398 | F7: ='Base Result'!F25 -> 0.053690444 | G7: ='Base Result'!G25 -> 0.035340917 | H7: ='Base Result'!H25 -> 0.76416278 | I7: ='Base Result'!I25 -> 0.80406911 | ... CW7: ='Base Result'!CW25 -> 0.71517479 | CY7: feature_23 | CZ7: area3 | DA7: {=SUMPRODUCT((B7:CW7>B$32:CW$32)*1)} -> 65 | DB7: =AVERAGE(B7:CW7) -> 0.56518338 | DC7: =MEDIAN(B7:CW7) -> 0.62738048 | DD7: =_xlfn.STDEV.S(B7:CW7) -> 0.29065079
A8: feature_04 | B8: ='Base Result'!B6 -> 0.79976312 | C8: ='Base Result'!C6 -> 0.94418188 | D8: ='Base Result'!D6 -> 0.69942319 | E8: ='Base Result'!E6 -> 0.8068077 | F8: ='Base Result'!F6 -> 0.41807994 | G8: ='Base Result'!G6 -> 0.19882407 | H8: ='Base Result'!H6 -> 0.73740437 | I8: ='Base Result'!I6 -> 0.85402535 | ... CW8: ='Base Result'!CW6 -> 0.69874364 | CY8: feature_04 | CZ8: smoothness1 | DA8: {=SUMPRODUCT((B8:CW8>B$32:CW$32)*1)} -> 64 | DB8: =AVERAGE(B8:CW8) -> 0.55414287 | DC8: =MEDIAN(B8:CW8) -> 0.58424041 | DD8: =_xlfn.STDEV.S(B8:CW8) -> 0.27427805
A9: feature_19 | B9: ='Base Result'!B21 -> 0.35606599 | C9: ='Base Result'!C21 -> 0.54162586 | D9: ='Base Result'!D21 -> 0.38741661 | E9: ='Base Result'!E21 -> 0.46230624 | F9: ='Base Result'!F21 -> 0.38874823 | G9: ='Base Result'!G21 -> 0.3470052 | H9: ='Base Result'!H21 -> 0.35159295 | I9: ='Base Result'!I21 -> 0.50693083 | ... CW9: ='Base Result'!CW21 -> 0.40945765 | CY9: feature_19 | CZ9: fractal_dimension2 | DA9: {=SUMPRODUCT((B9:CW9>B$32:CW$32)*1)} -> 64 | DB9: =AVERAGE(B9:CW9) -> 0.54248362 | DC9: =MEDIAN(B9:CW9) -> 0.56586078 | DD9: =_xlfn.STDEV.S(B9:CW9) -> 0.2681525
A10: feature_03 | B10: ='Base Result'!B5 -> 0.40153715 | C10: ='Base Result'!C5 -> 0.58747925 | D10: ='Base Result'!D5 -> 0.35297716 | E10: ='Base Result'!E5 -> 0.96568025 | F10: ='Base Result'!F5 -> 0.90069367 | G10: ='Base Result'!G5 -> 0.24607067 | H10: ='Base Result'!H5 -> 0.012995297 | I10: ='Base Result'!I5 -> 0.76251718 | ... CW10: ='Base Result'!CW5 -> 0.43111131 | CY10: feature_03 | CZ10: area1 | DA10: {=SUMPRODUCT((B10:CW10>B$32:CW$32)*1)} -> 61 | DB10: =AVERAGE(B10:CW10) -> 0.52575756 | DC10: =MEDIAN(B10:CW10) -> 0.52124624 | DD10: =_xlfn.STDEV.S(B10:CW10) -> 0.28507564
A11: feature_07 | B11: ='Base Result'!B9 -> 0.42522801 | C11: ='Base Result'!C9 -> 0.76067873 | D11: ='Base Result'!D9 -> 0.84765267 | E11: ='Base Result'!E9 -> 0.88979982 | F11: ='Base Result'!F9 -> 0.91890718 | G11: ='Base Result'!G9 -> 0.40342313 | H11: ='Base Result'!H9 -> 0.050232562 | I11: ='Base Result'!I9 -> 0.40654916 | ... CW11: ='Base Result'!CW9 -> 0.37734011 | CY11: feature_07 | CZ11: concave_points1 | DA11: {=SUMPRODUCT((B11:CW11>B$32:CW$32)*1)} -> 60 | DB11: =AVERAGE(B11:CW11) -> 0.56054429 | DC11: =MEDIAN(B11:CW11) -> 0.60502826 | DD11: =_xlfn.STDEV.S(B11:CW11) -> 0.3052529
A12: feature_08 | B12: ='Base Result'!B10 -> 0.26528154 | C12: ='Base Result'!C10 -> 0.82390002 | D12: ='Base Result'!D10 -> 0.69355088 | E12: ='Base Result'!E10 -> 0.042483226 | F12: ='Base Result'!F10 -> 0.73056947 | G12: ='Base Result'!G10 -> 0.71163036 | H12: ='Base Result'!H10 -> 0.8974848 | I12: ='Base Result'!I10 -> 0.4201504 | ... CW12: ='Base Result'!CW10 -> 0.17631597 | CY12: feature_08 | CZ12: symmetry1 | DA12: {=SUMPRODUCT((B12:CW12>B$32:CW$32)*1)} -> 60 | DB12: =AVERAGE(B12:CW12) -> 0.53989008 | DC12: =MEDIAN(B12:CW12) -> 0.60129107 | DD12: =_xlfn.STDEV.S(B12:CW12) -> 0.31503452
A13: feature_06 | B13: ='Base Result'!B8 -> 0.4651809 | C13: ='Base Result'!C8 -> 0.60686843 | D13: ='Base Result'!D8 -> 0.62307419 | E13: ='Base Result'!E8 -> 0.50537899 | F13: ='Base Result'!F8 -> 0.6046311 | G13: ='Base Result'!G8 -> 0.61443517 | H13: ='Base Result'!H8 -> 0.61839543 | I13: ='Base Result'!I8 -> 0.60691297 | ... CW13: ='Base Result'!CW8 -> 0.814814 | CY13: feature_06 | CZ13: concavity1 | DA13: {=SUMPRODUCT((B13:CW13>B$32:CW$32)*1)} -> 59 | DB13: =AVERAGE(B13:CW13) -> 0.56013193 | DC13: =MEDIAN(B13:CW13) -> 0.59335853 | DD13: =_xlfn.STDEV.S(B13:CW13) -> 0.28434344
A14: feature_10 | B14: ='Base Result'!B12 -> 0.72380161 | C14: ='Base Result'!C12 -> 0.32110336 | D14: ='Base Result'!D12 -> 0.38713395 | E14: ='Base Result'!E12 -> 0.057314798 | F14: ='Base Result'!F12 -> 0.034480395 | G14: ='Base Result'!G12 -> 0.016569401 | H14: ='Base Result'!H12 -> 0.54021323 | I14: ='Base Result'!I12 -> 0.31821149 | ... CW14: ='Base Result'!CW12 -> 0.58892107 | CY14: feature_10 | CZ14: radius2 | DA14: {=SUMPRODUCT((B14:CW14>B$32:CW$32)*1)} -> 59 | DB14: =AVERAGE(B14:CW14) -> 0.50198318 | DC14: =MEDIAN(B14:CW14) -> 0.51640173 | DD14: =_xlfn.STDEV.S(B14:CW14) -> 0.27571661
A15: feature_12 | B15: ='Base Result'!B14 -> 0.58470849 | C15: ='Base Result'!C14 -> 0.69751376 | D15: ='Base Result'!D14 -> 0.88716429 | E15: ='Base Result'!E14 -> 0.81747916 | F15: ='Base Result'!F14 -> 0.31054314 | G15: ='Base Result'!G14 -> 0.2115174 | H15: ='Base Result'!H14 -> 0.043895891 | I15: ='Base Result'!I14 -> 0.48765078 | ... CW15: ='Base Result'!CW14 -> 0.70952694 | CY15: feature_12 | CZ15: perimeter2 | DA15: {=SUMPRODUCT((B15:CW15>B$32:CW$32)*1)} -> 58 | DB15: =AVERAGE(B15:CW15) -> 0.52437301 | DC15: =MEDIAN(B15:CW15) -> 0.55162087 | DD15: =_xlfn.STDEV.S(B15:CW15) -> 0.28272145
A16: feature_02 | B16: ='Base Result'!B4 -> 0.78042869 | C16: ='Base Result'!C4 -> 0.9612421 | D16: ='Base Result'!D4 -> 0.27167539 | E16: ='Base Result'!E4 -> 0.94707735 | F16: ='Base Result'!F4 -> 0.87128414 | G16: ='Base Result'!G4 -> 0.64980513 | H16: ='Base Result'!H4 -> 0.86882055 | I16: ='Base Result'!I4 -> 0.17871908 | ... CW16: ='Base Result'!CW4 -> 0.025035977 | CY16: feature_02 | CZ16: perimeter1 | DA16: {=SUMPRODUCT((B16:CW16>B$32:CW$32)*1)} -> 57 | DB16: =AVERAGE(B16:CW16) -> 0.51076292 | DC16: =MEDIAN(B16:CW16) -> 0.54514807 | DD16: =_xlfn.STDEV.S(B16:CW16) -> 0.30134546
A17: feature_27 | B17: ='Base Result'!B29 -> 0.81924844 | C17: ='Base Result'!C29 -> 0.3162644 | D17: ='Base Result'!D29 -> 0.31044075 | E17: ='Base Result'!E29 -> 0.75658888 | F17: ='Base Result'!F29 -> 0.65357045 | G17: ='Base Result'!G29 -> 0.53478052 | H17: ='Base Result'!H29 -> 0.86276855 | I17: ='Base Result'!I29 -> 0.4866154 | ... CW17: ='Base Result'!CW29 -> 0.57253838 | CY17: feature_27 | CZ17: concave_points3 | DA17: {=SUMPRODUCT((B17:CW17>B$32:CW$32)*1)} -> 56 | DB17: =AVERAGE(B17:CW17) -> 0.54113773 | DC17: =MEDIAN(B17:CW17) -> 0.55721084 | DD17: =_xlfn.STDEV.S(B17:CW17) -> 0.2691165
A18: feature_01 | B18: ='Base Result'!B3 -> 0.27459702 | C18: ='Base Result'!C3 -> 0.37073133 | D18: ='Base Result'!D3 -> 0.66988846 | E18: ='Base Result'!E3 -> 0.12986359 | F18: ='Base Result'!F3 -> 0.94483872 | G18: ='Base Result'!G3 -> 0.67737206 | H18: ='Base Result'!H3 -> 0.12362852 | I18: ='Base Result'!I3 -> 0.027360411 | ... CW18: ='Base Result'!CW3 -> 0.91456197 | CY18: feature_01 | CZ18: texture1 | DA18: {=SUMPRODUCT((B18:CW18>B$32:CW$32)*1)} -> 55 | DB18: =AVERAGE(B18:CW18) -> 0.52347636 | DC18: =MEDIAN(B18:CW18) -> 0.50234194 | DD18: =_xlfn.STDEV.S(B18:CW18) -> 0.26033559
A19: feature_15 | B19: ='Base Result'!B17 -> 0.61634124 | C19: ='Base Result'!C17 -> 0.032164654 | D19: ='Base Result'!D17 -> 0.18240683 | E19: ='Base Result'!E17 -> 0.10809042 | F19: ='Base Result'!F17 -> 0.94389185 | G19: ='Base Result'!G17 -> 0.34205188 | H19: ='Base Result'!H17 -> 0.098573091 | I19: ='Base Result'!I17 -> 0.59835009 | ... CW19: ='Base Result'!CW17 -> 0.033732089 | CY19: feature_15 | CZ19: compactness2 | DA19: {=SUMPRODUCT((B19:CW19>B$32:CW$32)*1)} -> 55 | DB19: =AVERAGE(B19:CW19) -> 0.50258196 | DC19: =MEDIAN(B19:CW19) -> 0.47199771 | DD19: =_xlfn.STDEV.S(B19:CW19) -> 0.3010661
A20: feature_14 | B20: ='Base Result'!B16 -> 0.36083158 | C20: ='Base Result'!C16 -> 0.48217727 | D20: ='Base Result'!D16 -> 0.35931253 | E20: ='Base Result'!E16 -> 0.91821964 | F20: ='Base Result'!F16 -> 0.16425385 | G20: ='Base Result'!G16 -> 0.27881091 | H20: ='Base Result'!H16 -> 0.45118962 | I20: ='Base Result'!I16 -> 0.076688325 | ... CW20: ='Base Result'!CW16 -> 0.77142746 | CY20: feature_14 | CZ20: smoothness2 | DA20: {=SUMPRODUCT((B20:CW20>B$32:CW$32)*1)} -> 52 | DB20: =AVERAGE(B20:CW20) -> 0.48144078 | DC20: =MEDIAN(B20:CW20) -> 0.4598042 | DD20: =_xlfn.STDEV.S(B20:CW20) -> 0.27482483
A21: feature_18 | B21: ='Base Result'!B20 -> 0.31055897 | C21: ='Base Result'!C20 -> 0.99729927 | D21: ='Base Result'!D20 -> 0.54579883 | E21: ='Base Result'!E20 -> 0.78608964 | F21: ='Base Result'!F20 -> 0.60012936 | G21: ='Base Result'!G20 -> 0.28136763 | H21: ='Base Result'!H20 -> 0.37634592 | I21: ='Base Result'!I20 -> 0.64842897 | ... CW21: ='Base Result'!CW20 -> 0.048398945 | CY21: feature_18 | CZ21: symmetry2 | DA21: {=SUMPRODUCT((B21:CW21>B$32:CW$32)*1)} -> 52 | DB21: =AVERAGE(B21:CW21) -> 0.45754973 | DC21: =MEDIAN(B21:CW21) -> 0.41438092 | DD21: =_xlfn.STDEV.S(B21:CW21) -> 0.300911
A22: feature_13 | B22: ='Base Result'!B15 -> 0.93587571 | C22: ='Base Result'!C15 -> 0.91224409 | D22: ='Base Result'!D15 -> 0.83871929 | E22: ='Base Result'!E15 -> 0.0014707991 | F22: ='Base Result'!F15 -> 0.39187652 | G22: ='Base Result'!G15 -> 0.16384605 | H22: ='Base Result'!H15 -> 0.97100357 | I22: ='Base Result'!I15 -> 0.93247959 | ... CW22: ='Base Result'!CW15 -> 0.91140008 | CY22: feature_13 | CZ22: area2 | DA22: {=SUMPRODUCT((B22:CW22>B$32:CW$32)*1)} -> 51 | DB22: =AVERAGE(B22:CW22) -> 0.49542691 | DC22: =MEDIAN(B22:CW22) -> 0.45786409 | DD22: =_xlfn.STDEV.S(B22:CW22) -> 0.30301849
A23: feature_16 | B23: ='Base Result'!B18 -> 0.33257906 | C23: ='Base Result'!C18 -> 0.26009423 | D23: ='Base Result'!D18 -> 0.21100775 | E23: ='Base Result'!E18 -> 0.060710394 | F23: ='Base Result'!F18 -> 0.37185026 | G23: ='Base Result'!G18 -> 0.99413989 | H23: ='Base Result'!H18 -> 0.89209408 | I23: ='Base Result'!I18 -> 0.056853717 | ... CW23: ='Base Result'!CW18 -> 0.44595081 | CY23: feature_16 | CZ23: concavity2 | DA23: {=SUMPRODUCT((B23:CW23>B$32:CW$32)*1)} -> 51 | DB23: =AVERAGE(B23:CW23) -> 0.48948856 | DC23: =MEDIAN(B23:CW23) -> 0.46419033 | DD23: =_xlfn.STDEV.S(B23:CW23) -> 0.28768845
A24: feature_17 | B24: ='Base Result'!B19 -> 0.93679315 | C24: ='Base Result'!C19 -> 0.68601752 | D24: ='Base Result'!D19 -> 0.51781127 | E24: ='Base Result'!E19 -> 0.87867167 | F24: ='Base Result'!F19 -> 0.47386786 | G24: ='Base Result'!G19 -> 0.50725864 | H24: ='Base Result'!H19 -> 0.29413093 | I24: ='Base Result'!I19 -> 0.21931397 | ... CW24: ='Base Result'!CW19 -> 0.82604375 | CY24: feature_17 | CZ24: concave_points2 | DA24: {=SUMPRODUCT((B24:CW24>B$32:CW$32)*1)} -> 51 | DB24: =AVERAGE(B24:CW24) -> 0.47678034 | DC24: =MEDIAN(B24:CW24) -> 0.48668892 | DD24: =_xlfn.STDEV.S(B24:CW24) -> 0.30371687
A25: feature_29 | B25: ='Base Result'!B31 -> 0.38959726 | C25: ='Base Result'!C31 -> 0.90512487 | D25: ='Base Result'!D31 -> 0.31562149 | E25: ='Base Result'!E31 -> 0.87713344 | F25: ='Base Result'!F31 -> 0.20527957 | G25: ='Base Result'!G31 -> 0.78950686 | H25: ='Base Result'!H31 -> 0.83562534 | I25: ='Base Result'!I31 -> 0.93981151 | ... CW25: ='Base Result'!CW31 -> 0.86198773 | CY25: feature_29 | CZ25: fractal_dimension3 | DA25: {=SUMPRODUCT((B25:CW25>B$32:CW$32)*1)} -> 48 | DB25: =AVERAGE(B25:CW25) -> 0.48950573 | DC25: =MEDIAN(B25:CW25) -> 0.41295248 | DD25: =_xlfn.STDEV.S(B25:CW25) -> 0.3146255
A26: feature_00 | B26: ='Base Result'!B2 -> 0.72823858 | C26: ='Base Result'!C2 -> 0.034302115 | D26: ='Base Result'!D2 -> 0.35418245 | E26: ='Base Result'!E2 -> 0.56817993 | F26: ='Base Result'!F2 -> 0.27568886 | G26: ='Base Result'!G2 -> 0.21853824 | H26: ='Base Result'!H2 -> 0.34487651 | I26: ='Base Result'!I2 -> 0.86488439 | ... CW26: ='Base Result'!CW2 -> 0.7212224 | CY26: feature_00 | CZ26: radius1 | DA26: {=SUMPRODUCT((B26:CW26>B$32:CW$32)*1)} -> 47 | DB26: =AVERAGE(B26:CW26) -> 0.46752143 | DC26: =MEDIAN(B26:CW26) -> 0.44733669 | DD26: =_xlfn.STDEV.S(B26:CW26) -> 0.29494335
A27: feature_11 | B27: ='Base Result'!B13 -> 0.61897311 | C27: ='Base Result'!C13 -> 0.14814349 | D27: ='Base Result'!D13 -> 0.29809798 | E27: ='Base Result'!E13 -> 0.44958505 | F27: ='Base Result'!F13 -> 0.41798379 | G27: ='Base Result'!G13 -> 0.87577649 | H27: ='Base Result'!H13 -> 0.12870165 | I27: ='Base Result'!I13 -> 0.2188997 | ... CW27: ='Base Result'!CW13 -> 0.10237763 | CY27: feature_11 | CZ27: texture2 | DA27: {=SUMPRODUCT((B27:CW27>B$32:CW$32)*1)} -> 44 | DB27: =AVERAGE(B27:CW27) -> 0.44111344 | DC27: =MEDIAN(B27:CW27) -> 0.45167716 | DD27: =_xlfn.STDEV.S(B27:CW27) -> 0.27930804
A28: feature_25 | B28: ='Base Result'!B27 -> 0.20067716 | C28: ='Base Result'!C27 -> 0.88357432 | D28: ='Base Result'!D27 -> 0.16181977 | E28: ='Base Result'!E27 -> 0.27487778 | F28: ='Base Result'!F27 -> 0.9023659 | G28: ='Base Result'!G27 -> 0.80466348 | H28: ='Base Result'!H27 -> 0.4026813 | I28: ='Base Result'!I27 -> 0.18288298 | ... CW28: ='Base Result'!CW27 -> 0.30762539 | CY28: feature_25 | CZ28: compactness3 | DA28: {=SUMPRODUCT((B28:CW28>B$32:CW$32)*1)} -> 40 | DB28: =AVERAGE(B28:CW28) -> 0.41704006 | DC28: =MEDIAN(B28:CW28) -> 0.37406033 | DD28: =_xlfn.STDEV.S(B28:CW28) -> 0.27826874
A29: feature_09 | B29: ='Base Result'!B11 -> 0.48597387 | C29: ='Base Result'!C11 -> 0.74839635 | D29: ='Base Result'!D11 -> 0.45268193 | E29: ='Base Result'!E11 -> 0.16727412 | F29: ='Base Result'!F11 -> 0.5207187 | G29: ='Base Result'!G11 -> 0.18408112 | H29: ='Base Result'!H11 -> 0.21415763 | I29: ='Base Result'!I11 -> 0.27098313 | ... CW29: ='Base Result'!CW11 -> 0.65865451 | CY29: feature_09 | CZ29: fractal_dimension1 | DA29: {=SUMPRODUCT((B29:CW29>B$32:CW$32)*1)} -> 36 | DB29: =AVERAGE(B29:CW29) -> 0.41613179 | DC29: =MEDIAN(B29:CW29) -> 0.36998035 | DD29: =_xlfn.STDEV.S(B29:CW29) -> 0.28457132
A30: feature_05 | B30: ='Base Result'!B7 -> 0.44684522 | C30: ='Base Result'!C7 -> 0.11701641 | D30: ='Base Result'!D7 -> 0.17378828 | E30: ='Base Result'!E7 -> 0.25408169 | F30: ='Base Result'!F7 -> 0.010594784 | G30: ='Base Result'!G7 -> 0.53347962 | H30: ='Base Result'!H7 -> 0.19197591 | I30: ='Base Result'!I7 -> 0.48226388 | ... CW30: ='Base Result'!CW7 -> 0.048849431 | CY30: feature_05 | CZ30: compactness1 | DA30: {=SUMPRODUCT((B30:CW30>B$32:CW$32)*1)} -> 34 | DB30: =AVERAGE(B30:CW30) -> 0.36597331 | DC30: =MEDIAN(B30:CW30) -> 0.31558873 | DD30: =_xlfn.STDEV.S(B30:CW30) -> 0.24512929
A31: feature_28 | B31: ='Base Result'!B30 -> 0.66011083 | C31: ='Base Result'!C30 -> 0.64906688 | D31: ='Base Result'!D30 -> 0.24477904 | E31: ='Base Result'!E30 -> 0.76922847 | F31: ='Base Result'!F30 -> 0.39695736 | G31: ='Base Result'!G30 -> 0.028406512 | H31: ='Base Result'!H30 -> 0.081855689 | I31: ='Base Result'!I30 -> 0.43374131 | ... CW31: ='Base Result'!CW30 -> 0.76627608 | CY31: feature_28 | CZ31: symmetry3 | DA31: {=SUMPRODUCT((B31:CW31>B$32:CW$32)*1)} -> 32 | DB31: =AVERAGE(B31:CW31) -> 0.40319616 | DC31: =MEDIAN(B31:CW31) -> 0.38201113 | DD31: =_xlfn.STDEV.S(B31:CW31) -> 0.28136573
A32: threshold | B32: ='Base Result'!B32 -> 0.5006197 | C32: ='Base Result'!C32 -> 0.38950674 | D32: ='Base Result'!D32 -> 0.36464945 | E32: ='Base Result'!E32 -> 0.31817784 | F32: ='Base Result'!F32 -> 0.54530236 | G32: ='Base Result'!G32 -> 0.32377361 | H32: ='Base Result'!H32 -> 0.38457595 | I32: ='Base Result'!I32 -> 0.63727887 | ... CW32: ='Base Result'!CW32 -> 0.33380133 | CY32: threshold | DA32: {=SUMPRODUCT((B32:CW32>B$32:CW$32)*1)} -> 0 | DB32: =AVERAGE(B32:CW32) -> 0.45997737 | DC32: =MEDIAN(B32:CW32) -> 0.47994019 | DD32: =_xlfn.STDEV.S(B32:CW32) -> 0.14177206

Sheet Sheet1
A1: Feature | B1: Feature Name | C1: run 1 | D1: run 2 | E1: run 3 | F1: run 4 | G1: run 5 | H1: run 6 | I1: run 7 | J1: run 8 | K1: run 9 | L1: run 10 | M1: run 11 | N1: run 12 | O1: run 13 | P1: run 14 | Q1: run 15 | R1: run 16 | S1: run 17 | T1: run 18 | U1: run 19 | V1: run 20 | W1: run 21 | X1: run 22 | Y1: run 23 | Z1: run 24 | AA1: run 25 | AB1: run 26 | AC1: run 27 | AD1: run 28 | AE1: run 29 | AF1: run 30 | AG1: run 31 | AH1: run 32 | AI1: run 33 | AJ1: run 34 | AK1: run 35 | AL1: run 36 | AM1: run 37 | AN1: run 38 | AO1: run 39 | AP1: run 40 | AQ1: run 41 | AR1: run 42 | AS1: run 43 | AT1: run 44 | AU1: run 45 | AV1: run 46 | AW1: run 47 | AX1: run 48 | AY1: run 49 | AZ1: run 50 | BA1: run 51 | BB1: run 52 | BC1: run 53 | BD1: run 54 | BE1: run 55 | BF1: run 56 | BG1: run 57 | BH1: run 58 | BI1: run 59 | BJ1: run 60 | BK1: run 61 | BL1: run 62 | BM1: run 63 | BN1: run 64 | BO1: run 65 | BP1: run 66 | BQ1: run 67 | BR1: run 68 | BS1: run 69 | BT1: run 70 | BU1: run 71 | BV1: run 72 | BW1: run 73 | BX1: run 74 | BY1: run 75 | BZ1: run 76 | CA1: run 77 | CB1: run 78 | CC1: run 79 | CD1: run 80 | CE1: run 81 | CF1: run 82 | CG1: run 83 | CH1: run 84 | CI1: run 85 | CJ1: run 86 | CK1: run 87 | CL1: run 88 | CM1: run 89 | CN1: run 90 | CO1: run 91 | CP1: run 92 | CQ1: run 93 | CR1: run 94 | CS1: run 95 | CT1: run 96 | CU1: run 97 | CV1: run 98 | CW1: run 99 | CX1: run 100 | CY1: Feature | CZ1: Feature Name | DB1: Mean
A2: feature_00 | B2: radius1 | C2: 0.72823858 | D2: 0.034302115 | E2: 0.35418245 | F2: 0.56817993 | G2: 0.27568886 | H2: 0.21853824 | I2: 0.34487651 | J2: 0.86488439 | K2: 0.15340423 | L2: 0.032392317 | M2: 0.098237241 | N2: 0.12547285 | O2: 0.24182605 | P2: 0.59197505 | Q2: 0.35476647 | R2: 0.56785308 | S2: 0.49109554 | T2: 0.20710014 | U2: 0.53079905 | V2: 0.87154546 | W2: 0.38242396 | X2: 0.88803294 | Y2: 0.039847811 | Z2: 0.83121786 | AA2: 0.44396213 | AB2: 0.10904679 | AC2: 0.51892134 | AD2: 0.19859396 | AE2: 0.21283148 | AF2: 0.85241239 | AG2: 0.03346206 | AH2: 0.9853486 | AI2: 0.011566898 | AJ2: 0.3388596 | AK2: 0.26972115 | AL2: 0.41628081 | AM2: 0.93315195 | AN2: 0.11615611 | AO2: 0.27763366 | AP2: 0.57529027 | AQ2: 0.82988869 | AR2: 0.97223793 | AS2: 0.29461913 | AT2: 0.77810429 | AU2: 0.29915542 | AV2: 0.84327211 | AW2: 0.63171445 | AX2: 0.39941723 | AY2: 0.15109508 | AZ2: 0.83399044 | BA2: 0.92618472 | BB2: 0.78643047 | BC2: 0.68805124 | BD2: 0.29086524 | BE2: 0.16950503 | BF2: 0.060819164 | BG2: 0.86639739 | BH2: 0.49148433 | BI2: 0.80310751 | BJ2: 0.3217747 | BK2: 0.90942356 | BL2: 0.47597607 | BM2: 0.14266153 | BN2: 0.47535223 | BO2: 0.28329151 | BP2: 0.30603561 | BQ2: 0.12372115 | BR2: 0.18129173 | BS2: 0.0037563246 | BT2: 0.4318913 | BU2: 0.87782231 | BV2: 0.5057398 | BW2: 0.84388597 | BX2: 0.23224887 | BY2: 0.45071125 | BZ2: 0.70022703 | CA2: 0.47362872 | CB2: 0.26571207 | CC2: 0.15951176 | CD2: 0.9892445 | CE2: 0.46983714 | CF2: 0.5453564 | CG2: 0.75044983 | CH2: 0.50343381 | CI2: 0.49681864 | CJ2: 0.89656914 | CK2: 0.51549435 | CL2: 0.41894901 | CM2: 0.75613396 | CN2: 0.091308674 | CO2: 0.071811331 | CP2: 0.95654639 | CQ2: 0.84213134 | CR2: 0.25763406 | CS2: 0.33808668 | CT2: 0.071053631 | CU2: 0.13939165 | CV2: 0.94470212 | CW2: 0.60484422 | CX2: 0.7212224 | CY2: feature_00 | CZ2: radius1
A3: feature_01 | B3: texture1 | C3: 0.27459702 | D3: 0.37073133 | E3: 0.66988846 | F3: 0.12986359 | G3: 0.94483872 | H3: 0.67737206 | I3: 0.12362852 | J3: 0.027360411 | K3: 0.28819249 | L3: 0.2957189 | M3: 0.8291373 | N3: 0.10289321 | O3: 0.27582377 | P3: 0.58347118 | Q3: 0.33625855 | R3: 0.35445327 | S3: 0.39019933 | T3: 0.63001407 | U3: 0.40103198 | V3: 0.31620992 | W3: 0.1224265 | X3: 0.33388919 | Y3: 0.60625392 | Z3: 0.23884857 | AA3: 0.48540571 | AB3: 0.73364478 | AC3: 0.34577698 | AD3: 0.34594894 | AE3: 0.89133575 | AF3: 0.657677 | AG3: 0.62729513 | AH3: 0.93500585 | AI3: 0.59074944 | AJ3: 0.52943133 | AK3: 0.54114855 | AL3: 0.45553222 | AM3: 0.78413069 | AN3: 0.76489278 | AO3: 0.23661747 | AP3: 0.93995527 | AQ3: 0.091546605 | AR3: 0.9902923 | AS3: 0.48204976 | AT3: 0.71522564 | AU3: 0.42901507 | AV3: 0.88070257 | AW3: 0.84944336 | AX3: 0.59519794 | AY3: 0.95553404 | AZ3: 0.45255224 | BA3: 0.54781088 | BB3: 0.24280248 | BC3: 0.32722203 | BD3: 0.44786753 | BE3: 0.53993311 | BF3: 0.6671553 | BG3: 0.3086395 | BH3: 0.94819902 | BI3: 0.29693496 | BJ3: 0.53534172 | BK3: 0.76214339 | BL3: 0.44744653 | BM3: 0.29893682 | BN3: 0.37579475 | BO3: 0.30410231 | BP3: 0.52136978 | BQ3: 0.50062593 | BR3: 0.49543788 | BS3: 0.2682421 | BT3: 0.50405794 | BU3: 0.41606003 | BV3: 0.27260898 | BW3: 0.23339469 | BX3: 0.87982961 | BY3: 0.119199 | BZ3: 0.37975549 | CA3: 0.87471091 | CB3: 0.77702475 | CC3: 0.77592391 | CD3: 0.80374726 | CE3: 0.63175809 | CF3: 0.018544428 | CG3: 0.2681219 | CH3: 0.95468095 | CI3: 0.94875878 | CJ3: 0.34442577 | CK3: 0.53363191 | CL3: 0.64347479 | CM3: 0.5445629 | CN3: 0.18855902 | CO3: 0.44876961 | CP3: 0.94562178 | CQ3: 0.077204093 | CR3: 0.75984785 | CS3: 0.78589289 | CT3: 0.44213164 | CU3: 0.90129674 | CV3: 0.80529428 | CW3: 0.6889679 | CX3: 0.91456197 | CY3: feature_01 | CZ3: texture1
